<?xml version="1.0" ?>
<robot name="2DoF">
  <!--Generated by RobotCAD, a ROS Workbench for FreeCAD (https://github.com/drfenixion/freecad.robotcad)-->
  <link name="base">
    <visual>
      <!--Base/Body.-->
      <origin rpy="0 0 0" xyz="0.0 0.0 0.0"/>
      <geometry>
        <mesh filename="file:///home/alejandro/archivos_URDF/archivos_URDF/meshes/robot_1_eslabon_base_3nznlr.dae" scale = "1 1 1" />
      </geometry>
    </visual>
    <collision>
      <!--Base/Body.-->
      <origin rpy="0 0 0" xyz="0.0 0.0 0.0"/>
      <geometry>
        <mesh filename="file:///home/alejandro/archivos_URDF/archivos_URDF/meshes/robot_1_eslabon_base_bdywcl.dae" scale = "1 1 1"/>
      </geometry>
    </collision>
    <inertial>
      <mass value="9.568034585773075"/>
      <origin rpy="0 0 0" xyz="0.0 0.0 0.0251064"/>
      <inertia ixx="0.055708246279652" ixy="0.0" ixz="-0.0" iyy="0.0557082462796509" iyz="-0.0" izz="0.107355383807114"/>
    </inertial>
  </link>
  <link name="ESLABON_1">
    <visual>
      <!--Eslabon_1/Body001.-->
      <origin rpy="0 0 0" xyz="0.0 0.0 0.0"/>
      <geometry>
        <mesh filename="file:///home/alejandro/archivos_URDF/archivos_URDF/meshes/robot_1_eslabon_eslabon_1_yqpgga.dae" sacale = "1 1 1"/>
      </geometry>
    </visual>
    <collision>
      <!--Eslabon_1/Body001.-->
      <origin rpy="0 0 0" xyz="0.0 0.0 0.0"/>
      <geometry>
        <mesh filename="file:///home/alejandro/archivos_URDF/archivos_URDF/meshes/robot_1_eslabon_eslabon_1_lqzffo.dae" scale = "1 1 1"/>
      </geometry>
    </collision>
    <inertial>
      <mass value="0.9305169950293276"/>
      <origin rpy="0 0 0" xyz="0.156476 0.0 0.0116331"/>
      <inertia ixx="0.0002481881932751" ixy="2.57367322e-08" ixz="-0.0002029272118071" iyy="0.0087953923684969" iyz="2.2982102e-09" izz="0.0089293994448601"/>
    </inertial>
  </link>
  <link name="ESLABON_2">
    <visual>
      <!--Eslabon_2/Body002.-->
      <origin rpy="0 0 0" xyz="0.0 0.0 0.0"/>
      <geometry>
        <mesh filename="file:///home/alejandro/archivos_URDF/archivos_URDF/meshes/robot_1_eslabon_eslabon_2_hzqcl6.dae" scale ="1 1 1"/>
      </geometry>
    </visual>
    <collision>
      <!--Eslabon_2/Body002.-->
      <origin rpy="0 0 0" xyz="0.0 0.0 0.0"/>
      <geometry>
        <mesh filename="file:///home/alejandro/archivos_URDF/archivos_URDF/meshes/robot_1_eslabon_eslabon_2_byqzaf.dae" scale = "1 1 1"/>
      </geometry>
    </collision>
    <inertial>
      <mass value="0.17298517537055796"/>
      <origin rpy="0 0 0" xyz="0.0404838 0.0 0.0165997"/>
      <inertia ixx="3.18428116679068e-05" ixy="1.623500074969544e-21" ixz="-1.5105296416725162e-05" iyy="0.00010579825162053289" iyz="1.6848769728853109e-22" izz="9.918752488181383e-05"/>
    </inertial>
  </link>
  <joint name="Joint_1" type="revolute">
    <parent link="base"/>
    <child link="ESLABON_1"/>
    <origin rpy="0 0 0" xyz="0.0 0.0 0.05"/>
    <axis xyz="0 0 1"/>
    <limit effort="0.0" lower="-3.141592653589793" upper="3.141592653589793" velocity="0.017453292519943295"/>
  </joint>
  <joint name="Joint_eslabon1_eslabon2" type="revolute">
    <parent link="ESLABON_1"/>
    <child link="ESLABON_2"/>
    <origin rpy="1.5707963267948968 0 1.5707963267948966" xyz="0.3 0.0 0.02"/>
    <axis xyz="0 0 1"/>
    <limit effort="0.0" lower="-3.141592653589793" upper="3.141592653589793" velocity="0.017453292519943295"/>
  </joint>
</robot>
