<?xml version="1.0" ?>
<robot name="1DoF">

  <link name="world"/>

  <joint name="world_to_base_joint" type="fixed">
    <parent link="world"/>
    <child link="base"/>
    <origin xyz="0 0 0" rpy="0 0 0"/>
  </joint>

  <link name="base">
    <visual>
      <origin rpy="0 0 0" xyz="0 0 0"/>
      <geometry>
        <mesh filename="file:///home/alejandro/archivos_URDF/archivos_URDF/meshes/robot_1_eslabon_base_6c5ogp.dae" scale="1 1 1"/>
      </geometry>
    </visual>
    <collision>
      <origin rpy="0 0 0" xyz="0 0 0"/>
      <geometry>
        <mesh filename="file:///home/alejandro/archivos_URDF/archivos_URDF/meshes/robot_1_eslabon_base_hdh8ug.dae" scale="1 1 1"/>
      </geometry>
    </collision>
    <inertial>
      <mass value="9.568034585773075"/>
      <origin rpy="0 0 0" xyz="0.0 0.0 0.0251064"/>
      <inertia ixx="0.055708246279652" ixy="0.0" ixz="-0.0" iyy="0.0557082462796509" iyz="-0.0" izz="0.107355383807114"/>
    </inertial>
  </link>

  <link name="ESLABON_1">
    <visual>
      <origin rpy="0 0 0" xyz="0 0 0"/>
      <geometry>
        <mesh filename="file:///home/alejandro/archivos_URDF/archivos_URDF/meshes/robot_1_eslabon_eslabon_1_lrddyx.dae" scale="1 1 1"/>
      </geometry>
    </visual>
    <collision>
      <origin rpy="0 0 0" xyz="0 0 0"/>
      <geometry>
        <mesh filename="file:///home/alejandro/archivos_URDF/archivos_URDF/meshes/robot_1_eslabon_eslabon_1_hieewq.dae" scale="1 1 1"/>
      </geometry>
    </collision>
    <inertial>
      <mass value="0.9305169950293276"/>
      <origin rpy="0 0 0" xyz="0.156476 0.0 0.0116331"/>
      <inertia ixx="0.0002481881932751" ixy="2.57367322e-08" ixz="-0.0002029272118071" iyy="0.0087953923684969" iyz="2.2982102e-09" izz="0.0089293994448601"/>
    </inertial>
  </link>

  <joint name="Joint_1" type="revolute">
    <parent link="base"/>
    <child link="ESLABON_1"/>
    <origin rpy="0 0 0" xyz="0.0 0.0 0.05"/>
    <axis xyz="0 0 1"/>
    <limit effort="10.0" lower="-3.14" upper="3.14" velocity="1.0"/>
  </joint>

</robot>