<?xml version="1.0" ?>
<robot name="Robot">
  <!--Generated by RobotCAD, a ROS Workbench for FreeCAD (https://github.com/drfenixion/freecad.robotcad)-->
  <link name="BASE">
    <visual>
      <!--Base/Body.-->
      <origin rpy="0 0 0" xyz="0.0 0.0 0.0"/>
      <geometry>
        <mesh filename="file:///home/alejandro/archivos_URDF/archivos_URDF/meshes/_dof_base_sm6fop.dae" scale="1 1 1"/>
      </geometry>
    </visual>
    <collision>
      <!--Base/Body.-->
      <origin rpy="0 0 0" xyz="0.0 0.0 0.0"/>
      <geometry>
        <mesh filename="file:///home/alejandro/archivos_URDF/archivos_URDF/meshes/_dof_base_2whpfp.dae" scale="1 1 1"/>
      </geometry>
    </collision>
    <collision>
      <!--col__BASE__col_Part__BoundCylinder/col_Part__BoundCylinder.-->
      <origin rpy="0 0 0" xyz="1.93221e-05 0.0 0.035"/>
      <geometry>
        <cylinder length="0.07" radius="0.1414008618635786"/>
      </geometry>
    </collision>
    <inertial>
      <mass value="4.258114682675607"/>
      <origin rpy="0 0 0" xyz="0.0 0.0 0.0251394"/>
      <inertia ixx="0.01150813658411705" ixy="1.1349869656579396e-18" ixz="7.100964282301671e-19" iyy="0.01150813658411683" iyz="-1.291161653564965e-19" izz="0.021206598644447686"/>
    </inertial>
  </link>

  <link name="ESLABON_1">
    <visual>
      <!--Eslabon_1/Body001.-->
      <origin rpy="0 0 0" xyz="0.0 0.0 0.0"/>
      <geometry>
        <mesh filename="file:///home/alejandro/archivos_URDF/archivos_URDF/meshes/_dof_eslabon_1_fk8e70.dae" scale="1 1 1"/>
      </geometry>
    </visual>
    <collision>
      <!--Eslabon_1/Body001.-->
      <origin rpy="0 0 0" xyz="0.0 0.0 0.0"/>
      <geometry>
        <mesh filename="file:///home/alejandro/archivos_URDF/archivos_URDF/meshes/_dof_eslabon_1_x835yn.dae" scale="1 1 1"/>
      </geometry>
    </collision>
    <collision>
      <!--col__ESLABON_1__col_Part001__BoundBox/col_Part001__BoundBox.-->
      <origin rpy="0 0 0" xyz="0.160005 0.0 0.02"/>
      <geometry>
        <box size="0.3699905076756238 0.05 0.04"/>
      </geometry>
    </collision>
    <inertial>
      <mass value="1.0655143760293277"/>
      <origin rpy="0 0 0" xyz="0.176642 0.0 0.0126932"/>
      <inertia ixx="0.0003025646953363556" ixy="-3.260735601258474e-20" ixz="-0.00035993193854548533" iyy="0.011822527069211317" iyz="-7.933234151969565e-21" izz="0.011958404369084115"/>
    </inertial>
  </link>

  <link name="ESLABON_2">
    <visual>
      <!--Eslabon_2/Body002.-->
      <origin rpy="0 0 0" xyz="0.0 0.0 0.0"/>
      <geometry>
        <mesh filename="file:///home/alejandro/archivos_URDF/archivos_URDF/meshes/_dof_eslabon_2_xuxxuu.dae" scale="1 1 1"/>
      </geometry>
    </visual>
    <collision>
      <!--Eslabon_2/Body002.-->
      <origin rpy="0 0 0" xyz="0.0 0.0 0.0"/>
      <geometry>
        <mesh filename="file:///home/alejandro/archivos_URDF/archivos_URDF/meshes/_dof_eslabon_2_fjjgcd.dae" scale="1 1 1"/>
      </geometry>
    </collision>
    <collision>
      <!--col__ESLABON_2__col_Part002__BoundBox/col_Part002__BoundBox.-->
      <origin rpy="0 0 0" xyz="0.0375028 0.0 0.02"/>
      <geometry>
        <box size="0.10499430460537426 0.03 0.04"/>
      </geometry>
    </collision>
    <inertial>
      <mass value="0.19728517537055795"/>
      <origin rpy="0 0 0" xyz="0.0428044 0.0 0.0174291"/>
      <inertia ixx="3.760141328986979e-05" ixy="-3.9223889103740314e-22" ixz="-1.563562359469306e-05" iyy="0.00012734251589162517" iyz="-3.6317630094148834e-22" izz="0.00011861818753094319"/>
    </inertial>
  </link>

  <link name="ESLABON_3">
    <visual>
      <!--Eslabon_3/Body003.-->
      <origin rpy="0 0 0" xyz="0.0 0.0 0.0"/>
      <geometry>
        <mesh filename="file:///home/alejandro/archivos_URDF/archivos_URDF/meshes/_dof_eslabon_3_vsgxbz.dae" scale="1 1 1"/>
      </geometry>
    </visual>
    <collision>
      <!--Eslabon_3/Body003.-->
      <origin rpy="0 0 0" xyz="0.0 0.0 0.0"/>
      <geometry>
        <mesh filename="file:///home/alejandro/archivos_URDF/archivos_URDF/meshes/_dof_eslabon_3_33cubu.dae" scale="1 1 1"/>
      </geometry>
    </collision>
    <collision>
      <!--col__ESLABON_3__col_Part003__BoundBox/col_Part003__BoundBox.-->
      <origin rpy="0 0 0" xyz="0.160005 0.0 0.02"/>
      <geometry>
        <box size="0.3699905076756238 0.05 0.04"/>
      </geometry>
    </collision>
    <inertial>
      <mass value="1.0655143760293277"/>
      <origin rpy="0 0 0" xyz="0.176642 0.0 0.0126932"/>
      <inertia ixx="0.0003025646953363556" ixy="-3.260735601258474e-20" ixz="-0.00035993193854548533" iyy="0.011822527069211317" iyz="-7.933234151969565e-21" izz="0.011958404369084115"/>
    </inertial>
  </link>

  <link name="ESLABON_4">
    <visual>
      <!--Eslabon_4/Body004.-->
      <origin rpy="0 0 0" xyz="0.0 0.0 0.0"/>
      <geometry>
        <mesh filename="file:///home/alejandro/archivos_URDF/archivos_URDF/meshes/_dof_eslabon_4_qov1i0.dae" scale="1 1 1"/>
      </geometry>
    </visual>
    <collision>
      <!--Eslabon_4/Body004.-->
      <origin rpy="0 0 0" xyz="0.0 0.0 0.0"/>
      <geometry>
        <mesh filename="file:///home/alejandro/archivos_URDF/archivos_URDF/meshes/_dof_eslabon_4_ao5rln.dae" scale="1 1 1"/>
      </geometry>
    </collision>
    <collision>
      <!--col__ESLABON_4__col_Part004__BoundBox/col_Part004__BoundBox.-->
      <origin rpy="0 0 0" xyz="0.0375028 0.0 0.02"/>
      <geometry>
        <box size="0.10499430460537426 0.03 0.04"/>
      </geometry>
    </collision>
    <inertial>
      <mass value="0.19728517537055795"/>
      <origin rpy="0 0 0" xyz="0.0428044 0.0 0.0174291"/>
      <inertia ixx="3.760141328986979e-05" ixy="-3.9578950807669796e-22" ixz="-1.563562359469306e-05" iyy="0.00012734251589162517" iyz="-2.2321800334166616e-22" izz="0.00011861818753094319"/>
    </inertial>
  </link>

  <joint name="Joint_base_eslabon1" type="continuous">
    <parent link="BASE"/>
    <child link="ESLABON_1"/>
    <origin rpy="0 0 0" xyz="0.0 0.0 0.05"/>
    <axis xyz="0 0 1"/>
  </joint>
  <joint name="Joint_eslabon_1_eslabon_2" type="continuous">
    <parent link="ESLABON_1"/>
    <child link="ESLABON_2"/>
    <origin rpy="1.5707963267948968 0 1.5707963267948966" xyz="0.325 0.0 0.02"/>
    <axis xyz="0 0 1"/>
  </joint>
  <joint name="Joint_eslabon_2_eslabon_3" type="revolute">
    <parent link="ESLABON_2"/>
    <child link="ESLABON_3"/>
    <origin rpy="1.5707963267948963 0 1.5707963267948963" xyz="0.07 0.0 0.02"/>
    <axis xyz="0 0 1"/>
    <limit effort="10.0" lower="-3.14159" upper="3.14159" velocity="1.5708"/>
  </joint>
  <joint name="Joint_eslabon_3_eslabon_4" type="revolute">
    <parent link="ESLABON_3"/>
    <child link="ESLABON_4"/>
    <origin rpy="1.5707963267948966 0 1.5707963267948963" xyz="0.325 0.0 0.02"/>
    <axis xyz="0 0 1"/>
    <limit effort="10.0" lower="-3.14159" upper="3.14159" velocity="1.5708"/>
  </joint>
</robot>