<?xml version="1.0" ?>
<robot name="Robot">
  <!--Generated by RobotCAD, a ROS Workbench for FreeCAD (https://github.com/drfenixion/freecad.robotcad)-->
  <link name="Base">
    <visual>
      <!--Base001/Body.-->
      <origin rpy="0 0 0" xyz="0.0 0.0 0.0"/>
      <geometry>
        <mesh filename="package://robot_6dof_description/meshes/robot_6dof_base_x9wae5.dae" scale="1 1 1"/>
      </geometry>
    </visual>
    <collision>
      <!--Base001/Body.-->
      <origin rpy="0 0 0" xyz="0.0 0.0 0.0"/>
      <geometry>
        <mesh filename="package://robot_6dof_description/meshes/robot_6dof_base_2rkxk0.dae" scale="1 1 1"/>
      </geometry>
    </collision>
    <collision>
      <!--col__BAse__col_Pad001__BoundCylinder/col_Pad001__BoundCylinder.-->
      <origin rpy="0 0 0" xyz="1.93221e-05 0.0 0.035"/>
      <geometry>
        <cylinder length="0.07" radius="0.1414008618635786"/>
      </geometry>
    </collision>
    <inertial>
      <mass value="3.2645545900512984"/>
      <origin rpy="0 0 0" xyz="0.0 0.0 0.0251394"/>
      <inertia ixx="0.008822904714489738" ixy="8.70156673671087e-19" ixz="5.444072616431282e-19" iyy="0.008822904714489568" iyz="-9.898906010664731e-20" izz="0.016258392294076558"/>
    </inertial>
  </link>
  <link name="Eslabon_1">
    <visual>
      <!--Eslabon_1/Body001.-->
      <origin rpy="0 0 0" xyz= "0 0 0"/>
      <geometry>
        <mesh filename="package://robot_6dof_description/meshes/robot_6dof_eslabon_ma0lrf.dae" scale="1 1 1"/>
      </geometry>
    </visual>
    <collision>
      <!--Eslabon_1/Body001.-->
      <origin rpy="0 0 0" xyz="0 0 0"/>
      <geometry>
        <mesh filename="package://robot_6dof_description/meshes/robot_6dof_eslabon_35ca65.dae" scale="1 1 1"/>
      </geometry>
    </collision>
    <collision>
      <!--col__Eslabon__col_Pad004__BoundBox/col_Pad004__BoundBox.-->
      <origin rpy="0 0 0" xyz="0.287005 -0.0774998 -0.37"/>
      <geometry>
        <box size="0.3649905076756238 0.050000393000000004 0.035"/>
      </geometry>
    </collision>
    <inertial>
      <mass value="0.4397473430653209"/>
      <origin rpy="0 0 0" xyz="0.292245 -0.0775 -0.376627"/>
      <inertia ixx="0.00011046730705629365" ixy="-2.511608219688536e-09" ixz="-5.7704761645197515e-05" iyy="0.004557492814018955" iyz="-1.130301111864069e-10" izz="0.004627717386255992"/>
    </inertial>
  </link>
  <link name="Eslabon2">
    <visual>
      <!--Eslabon_2/Body002.-->
      <origin rpy="0 0 0" xyz="0.0 0.0 0.0"/>
      <geometry>
        <mesh filename="package://robot_6dof_description/meshes/robot_6dof_eslabon_003_kgpdci.dae" scale="1 1 1"/>
      </geometry>
    </visual>
    <collision>
      <!--Eslabon_2/Body002.-->
      <origin rpy="0 0 0" xyz="0.0 0.0 0.0"/>
      <geometry>
        <mesh filename="package://robot_6dof_description/meshes/robot_6dof_eslabon_003_stx6cg.dae" scale="1 1 1"/>
      </geometry>
    </collision>
    <collision>
      <!--col__Eslabon2__col_Body002__BoundBox/col_Body002__BoundBox.-->
      <origin rpy="0 0 0" xyz="0.499503 0.0 0.0175"/>
      <geometry>
        <box size="0.09499430460537428 0.030001334999999997 0.035"/>
      </geometry>
    </collision>
    <inertial>
      <mass value="0.06456537458351552"/>
      <origin rpy="0 0 0" xyz="0.503967 0.0 0.0139299"/>
      <inertia ixx="9.461474009139973e-06" ixy="-4.1317636875574807e-10" ixz="-4.475554559802108e-06" iyy="3.7125702465523034e-05" iyz="-1.4362546542662436e-10" izz="3.702044612858399e-05"/>
    </inertial>
  </link>
  <link name="Eslabon_3">
    <visual>
      <!--Eslabon_1/Body001.-->
      <origin rpy="0 0 0" xyz="0.0 0.0 0.0"/>
      <geometry>
        <mesh filename="package://robot_6dof_description/meshes/robot_6dof_eslabon_azz3rc.dae" scale="1 1 1"/>
      </geometry>
    </visual>
    <collision>
      <!--Eslabon_1/Body001.-->
      <origin rpy="0 0 0" xyz="0.0 0.0 0.0"/>
      <geometry>
        <mesh filename="package://robot_6dof_description/meshes/robot_6dof_eslabon_wivsgo.dae" scale="1 1 1"/>
      </geometry>
    </collision>
    <inertial>
      <mass value="0.4397473430653209"/>
      <origin rpy="0 0 0" xyz="0.162745 0.0 0.0108731"/>
      <inertia ixx="0.00011046730705629365" ixy="-2.511608219688536e-09" ixz="-5.7704761645197515e-05" iyy="0.004557492814018955" iyz="-1.130301111864069e-10" izz="0.004627717386255992"/>
    </inertial>
  </link>
  <link name="Eslabon_4">
    <visual>
      <!--Eslabon_2/Body002.-->
      <origin rpy="0 0 0" xyz="0.0 0.0 0.0"/>
      <geometry>
        <mesh filename="package://robot_6dof_description/meshes/robot_6dof_eslabon_003_rnysb1.dae" scale="1 1 1"/>
      </geometry>
    </visual>
    <collision>
      <!--Eslabon_2/Body002.-->
      <origin rpy="0 0 0" xyz="0.0 0.0 0.0"/>
      <geometry>
        <mesh filename="package://robot_6dof_description/meshes/robot_6dof_eslabon_003_xqcdmt.dae" scale="1 1 1"/>
      </geometry>
    </collision>
    <inertial>
      <mass value="0.06456537458351552"/>
      <origin rpy="0 0 0" xyz="0.503967 0.0 0.0139299"/>
      <inertia ixx="9.461474009139973e-06" ixy="-4.1317636875574807e-10" ixz="-4.475554559802108e-06" iyy="3.7125702465523034e-05" iyz="-1.4362546542662436e-10" izz="3.702044612858399e-05"/>
    </inertial>
  </link>
  <link name="Eslabon_5">
    <visual>
      <!--Eslabon_1/Body001.-->
      <origin rpy="0 0 0" xyz="0.0 0.0 0.0"/>
      <geometry>
        <mesh filename="package://robot_6dof_description/meshes/robot_6dof_eslabon_wckf2p.dae" scale="1 1 1"/>
      </geometry>
    </visual>
    <collision>
      <!--Eslabon_1/Body001.-->
      <origin rpy="0 0 0" xyz="0.0 0.0 0.0"/>
      <geometry>
        <mesh filename="package://robot_6dof_description/meshes/robot_6dof_eslabon_kpqsqe.dae" scale="1 1 1"/>
      </geometry>
    </collision>
    <inertial>
      <mass value="0.4397473430653209"/>
      <origin rpy="0 0 0" xyz="0.162745 0.0 0.0108731"/>
      <inertia ixx="0.00011046730705629365" ixy="-2.511608219688536e-09" ixz="-5.7704761645197515e-05" iyy="0.004557492814018955" iyz="-1.130301111864069e-10" izz="0.004627717386255992"/>
    </inertial>
  </link>
  <link name="Eslabon_6">
    <visual>
      <!--Eslabon_2/Body002.-->
      <origin rpy="0 0 0" xyz="0.0 0.0 0.0"/>
      <geometry>
        <mesh filename="package://robot_6dof_description/meshes/robot_6dof_eslabon_003_nphfiv.dae" scale="1 1 1"/>
      </geometry>
    </visual>
    <collision>
      <!--Eslabon_2/Body002.-->
      <origin rpy="0 0 0" xyz="0.0 0.0 0.0"/>
      <geometry>
        <mesh filename="package://robot_6dof_description/meshes/robot_6dof_eslabon_003_u51f5k.dae" scale="1 1 1"/>
      </geometry>
    </collision>
    <inertial>
      <mass value="0.06456537458351552"/>
      <origin rpy="0 0 0" xyz="0.503967 0.0 0.0139299"/>
      <inertia ixx="9.461474009139973e-06" ixy="-4.1317636875574807e-10" ixz="-4.475554559802108e-06" iyy="3.7125702465523034e-05" iyz="-1.4362546542662436e-10" izz="3.702044612858399e-05"/>
    </inertial>
  </link>
  <joint name="Joint" type="revolute">
    <parent link="Base"/>
    <child link="Eslabon_1"/>
    <origin rpy="0 0 0" xyz="-0.1295 0.0775 0.4375"/>
    <axis xyz="0 0 1"/>
    <limit effort="10.0" lower="-1.57" upper="1.57" velocity="1.0"/>
  </joint>
  <joint name="Joint_eslabon_1_2" type="revolute">
    <parent link="Eslabon_1"/>
    <child link="Eslabon2"/>
    <origin rpy="1.5707963267948968 0 1.5707963267948966" xyz="0.4495 -0.5445 -0.37"/>
    <axis xyz="0 0 1"/>
    <limit effort="10.0" lower="-1.57" upper="1.57" velocity="1.0"/>
  </joint>
  <joint name="Joint_2_3" type="revolute">
    <parent link="Eslabon2"/>
    <child link="Eslabon_3"/>
    <origin rpy="1.5707963267948963 0 1.5707963267948963" xyz="0.527 0.0 0.0175"/>
    <axis xyz="0 0 1"/>
    <limit effort="10.0" lower="-1.57" upper="1.57" velocity="1.0"/>
  </joint>
  <joint name="Joint_3_4" type="revolute">
    <parent link="Eslabon_3"/>
    <child link="Eslabon_4"/>
    <origin rpy="1.5707963267948963 0 1.5707963267948961" xyz="0.32 -0.467 0.0175"/>
    <axis xyz="0 0 1"/>
    <limit effort="10.0" lower="-1.57" upper="1.57" velocity="1.0"/>
  </joint>
  <joint name="Joint_4_5" type="revolute">
    <parent link="Eslabon_4"/>
    <child link="Eslabon_5"/>
    <origin rpy="1.5707963267948974 0 1.5707963267948968" xyz="0.527 0.0 0.0175"/>
    <axis xyz="0 0 1"/>
    <limit effort="10.0" lower="-1.57" upper="1.57" velocity="1.0"/>
  </joint>
  <joint name="Joint_5_6" type="revolute">
    <parent link="Eslabon_5"/>
    <child link="Eslabon_6"/>
    <origin rpy="1.5707963267948966 0 1.5707963267948974" xyz="0.32 -0.467 0.0175"/>
    <axis xyz="0 0 1"/>
    <limit effort="10.0" lower="-1.57" upper="1.57" velocity="1.0" />
  </joint>
</robot>
