<?xml version="1.0" ?>
<robot name="Robot">
  <!--Generated by RobotCAD, a ROS Workbench for FreeCAD (https://github.com/drfenixion/freecad.robotcad)-->
  <link name="BASE">
    <visual>
      <!--Base/Body.-->
      <origin rpy="0 0 0" xyz="0.0 0.0 0.0"/>
      <geometry>
        <mesh filename="file:///home/alejandro/archivos_URDF/archivos_URDF/meshes/unnamed_base_kxcain.dae" scale = "1 1 1"/>
      </geometry>
    </visual>
    <collision>
      <!--Base/Body.-->
      <origin rpy="0 0 0" xyz="0.0 0.0 0.0"/>
      <geometry>
        <mesh filename="file:///home/alejandro/archivos_URDF/archivos_URDF/meshes/unnamed_base_wn7p7b.dae" scale = "1 1 1"/>
      </geometry>
    </collision>
    <inertial>
      <mass value="4.258114682675607"/>
      <origin rpy="0 0 0" xyz="0.0 0.0 0.0251394"/>
      <inertia ixx="0.01150813658411705" ixy="1.1349869656579396e-18" ixz="7.100964282301671e-19" iyy="0.01150813658411683" iyz="-1.291161653564965e-19" izz="0.021206598644447686"/>
    </inertial>
  </link>
  <link name="ESLABON_1">
    <visual>
      <!--Eslabon_1/Body001.-->
      <origin rpy="0 0 0" xyz="0.0 0.0 0.0"/>
      <geometry>
        <mesh filename="file:///home/alejandro/archivos_URDF/archivos_URDF/meshes/unnamed_eslabon_1_dt3j5w.dae" scale = "1 1 1"/>
      </geometry>
    </visual>
    <collision>
      <!--Eslabon_1/Body001.-->
      <origin rpy="0 0 0" xyz="0.0 0.0 0.0"/>
      <geometry>
        <mesh filename="file:///home/alejandro/archivos_URDF/archivos_URDF/meshes/unnamed_eslabon_1_oam2om.dae" scale = "1 1 1"/>
      </geometry>
    </collision>
    <inertial>
      <mass value="1.0655143760293277"/>
      <origin rpy="0 0 0" xyz="0.176642 0.0 0.0126932"/>
      <inertia ixx="0.0003025646953363556" ixy="-3.260735601258474e-20" ixz="-0.00035993193854548533" iyy="0.011822527069211317" iyz="-7.933234151969565e-21" izz="0.011958404369084115"/>
    </inertial>
  </link>
  <link name="ESLABON_2">
    <visual>
      <!--Eslabon_2/Body002.-->
      <origin rpy="0 0 0" xyz="0.0 0.0 0.0"/>
      <geometry>
        <mesh filename="file:///home/alejandro/archivos_URDF/archivos_URDF/meshes/unnamed_eslabon_2_n3waks.dae" scale = "1 1 1"/>
      </geometry>
    </visual>
    <collision>
      <!--Eslabon_2/Body002.-->
      <origin rpy="0 0 0" xyz="0.0 0.0 0.0"/>
      <geometry>
        <mesh filename="file:///home/alejandro/archivos_URDF/archivos_URDF/meshes/unnamed_eslabon_2_lstjhs.dae" scale = "1 1 1"/>
      </geometry>
    </collision>
    <inertial>
      <mass value="0.19728517537055795"/>
      <origin rpy="0 0 0" xyz="0.0428044 0.0 0.0174291"/>
      <inertia ixx="3.760141328986979e-05" ixy="-3.9223889103740314e-22" ixz="-1.563562359469306e-05" iyy="0.00012734251589162517" iyz="-3.6317630094148834e-22" izz="0.00011861818753094319"/>
    </inertial>
  </link>
  <link name="ESLABON_3">
    <visual>
      <!--Eslabon_3/Body003.-->
      <origin rpy="0 0 0" xyz="0.0 0.0 0.0"/>
      <geometry>
        <mesh filename="file:///home/alejandro/archivos_URDF/archivos_URDF/meshes/unnamed_eslabon_3_zwa0vo.dae" scale = "1 1 1"/>
      </geometry>
    </visual>
    <collision>
      <!--Eslabon_3/Body003.-->
      <origin rpy="0 0 0" xyz="0.0 0.0 0.0"/>
      <geometry>
        <mesh filename="file:///home/alejandro/archivos_URDF/archivos_URDF/meshes/unnamed_eslabon_3_idlilt.dae" scale = "1 1 1"/>
      </geometry>
    </collision>
    <inertial>
      <mass value="1.0655143760293277"/>
      <origin rpy="0 0 0" xyz="0.176642 0.0 0.0126932"/>
      <inertia ixx="0.0003025646953363556" ixy="-3.260735601258474e-20" ixz="-0.00035993193854548533" iyy="0.011822527069211317" iyz="-7.933234151969565e-21" izz="0.011958404369084115"/>
    </inertial>
  </link>
  <joint name="Joint_base_eslabon1" type="continuous">
    <parent link="BASE"/>
    <child link="ESLABON_1"/>
    <origin rpy="0 0 0" xyz="0.0 0.0 0.05"/>
    <axis xyz="0 0 1"/>
  </joint>
  <joint name="Joint_eslabon_1_eslabon_2" type="continuous">
    <parent link="ESLABON_1"/>
    <child link="ESLABON_2"/>
    <origin rpy="1.5707963267948968 0 1.5707963267948966" xyz="0.325 0.0 0.02"/>
    <axis xyz="0 0 1"/>
  </joint>
  <joint name="Joint_eslabon_2_eslabon_3" type="revolute">
    <parent link="ESLABON_2"/>
    <child link="ESLABON_3"/>
    <origin rpy="1.5707963267948968 0 1.5707963267948968" xyz="0.07 0.0 0.02"/>
    <axis xyz="0 0 1"/>
    <limit effort="0.0" lower="-3.14" upper="3.14" velocity="1"/>
  </joint>
</robot>
